Traceback (most recent call last):
  File "/home/labeeb/hacks/hackniche/ai-backend/pyserver/mul.py", line 30, in <module>
    response = gemini.run(task=task)
  File "/home/labeeb/.local/lib/python3.10/site-packages/swarms/models/gemini.py", line 186, in run
    raise error
  File "/home/labeeb/.local/lib/python3.10/site-packages/swarms/models/gemini.py", line 176, in run
    response = self.model.generate_content(
  File "/home/labeeb/.local/lib/python3.10/site-packages/google/generativeai/generative_models.py", line 243, in generate_content
    response = self._client.generate_content(request)
  File "/home/labeeb/.local/lib/python3.10/site-packages/google/ai/generativelanguage_v1beta/services/generative_service/client.py", line 566, in generate_content
    response = rpc(
  File "/home/labeeb/.local/lib/python3.10/site-packages/google/api_core/gapic_v1/method.py", line 131, in __call__
    return wrapped_func(*args, **kwargs)
  File "/home/labeeb/.local/lib/python3.10/site-packages/google/api_core/retry/retry_unary.py", line 293, in retry_wrapped_func
    return retry_target(
  File "/home/labeeb/.local/lib/python3.10/site-packages/google/api_core/retry/retry_unary.py", line 153, in retry_target
    _retry_error_helper(
  File "/home/labeeb/.local/lib/python3.10/site-packages/google/api_core/retry/retry_base.py", line 212, in _retry_error_helper
    raise final_exc from source_exc
  File "/home/labeeb/.local/lib/python3.10/site-packages/google/api_core/retry/retry_unary.py", line 144, in retry_target
    result = target()
  File "/home/labeeb/.local/lib/python3.10/site-packages/google/api_core/timeout.py", line 120, in func_with_timeout
    return func(*args, **kwargs)
  File "/home/labeeb/.local/lib/python3.10/site-packages/google/api_core/grpc_helpers.py", line 76, in error_remapped_callable
    return callable_(*args, **kwargs)
  File "/home/labeeb/.local/lib/python3.10/site-packages/google/ai/generativelanguage_v1beta/services/generative_service/transports/rest.py", line 856, in __call__
    raise core_exceptions.from_http_response(response)
google.api_core.exceptions.BadRequest: 400 POST https://generativelanguage.googleapis.com/v1beta/models/gemini-pro-vision:generateContent?%24alt=json%3Benum-encoding%3Dint: API key not valid. Please pass a valid API key. [{'@type': 'type.googleapis.com/google.rpc.ErrorInfo', 'reason': 'API_KEY_INVALID', 'domain': 'googleapis.com', 'metadata': {'service': 'generativelanguage.googleapis.com'}}]
Implicitly cleaning up <TemporaryDirectory '/tmp/tmp0mfljs3g'>
